{
  "snapshot_0": {
    "duration": "<scrubbed>",
    "error": 1,
    "meta": {
      "_dd.debug.error.8.file": "/app/exception_replay_controller.py",
      "_dd.debug.error.8.function": "exceptionReplayRps",
      "_dd.debug.error.8.line": "40",
      "_dd.debug.error.8.snapshot_id": "<scrubbed>",
      "_dd.debug.error.exception_capture_id": "<scrubbed>",
      "_dd.debug.error.exception_hash": "<scrubbed>",
      "component": "flask",
      "env": "system-tests",
      "error.debug_info_captured": "true",
      "error.message": "paper exception",
      "error.stack": "Traceback (most recent call last):\n  File \"/usr/local/lib/python3.11/site-packages/ddtrace/contrib/internal/flask/wrappers.py\", <scrubbed>",
      "error.type": "debugger.exception_replay.ExceptionReplayPaper",
      "key1": "val1",
      "key2": "val2",
      "version": "<scrubbed>"
    },
    "name": "flask.handle_user_exception",
    "parentID": "<scrubbed>",
    "resource": "flask.handle_user_exception",
    "service": "weblog",
    "spanID": "<scrubbed>",
    "start": "<scrubbed>",
    "traceID": "<scrubbed>"
  },
  "snapshot_1": {
    "duration": "<scrubbed>",
    "error": 1,
    "meta": {
      "_dd.debug.error.8.file": "/app/exception_replay_controller.py",
      "_dd.debug.error.8.function": "exceptionReplayRps",
      "_dd.debug.error.8.line": "38",
      "_dd.debug.error.8.snapshot_id": "<scrubbed>",
      "_dd.debug.error.exception_capture_id": "<scrubbed>",
      "_dd.debug.error.exception_hash": "<scrubbed>",
      "component": "flask",
      "env": "system-tests",
      "error.debug_info_captured": "true",
      "error.message": "rock exception",
      "error.stack": "Traceback (most recent call last):\n  File \"/usr/local/lib/python3.11/site-packages/ddtrace/contrib/internal/flask/wrappers.py\", <scrubbed>",
      "error.type": "debugger.exception_replay.ExceptionReplayRock",
      "key1": "val1",
      "key2": "val2",
      "version": "<scrubbed>"
    },
    "name": "flask.handle_user_exception",
    "parentID": "<scrubbed>",
    "resource": "flask.handle_user_exception",
    "service": "weblog",
    "spanID": "<scrubbed>",
    "start": "<scrubbed>",
    "traceID": "<scrubbed>"
  },
  "snapshot_2": {
    "duration": "<scrubbed>",
    "error": 1,
    "meta": {
      "_dd.debug.error.8.file": "/app/exception_replay_controller.py",
      "_dd.debug.error.8.function": "exceptionReplayRps",
      "_dd.debug.error.8.line": "42",
      "_dd.debug.error.8.snapshot_id": "<scrubbed>",
      "_dd.debug.error.exception_capture_id": "<scrubbed>",
      "_dd.debug.error.exception_hash": "<scrubbed>",
      "component": "flask",
      "env": "system-tests",
      "error.debug_info_captured": "true",
      "error.message": "scissors exception",
      "error.stack": "Traceback (most recent call last):\n  File \"/usr/local/lib/python3.11/site-packages/ddtrace/contrib/internal/flask/wrappers.py\", <scrubbed>",
      "error.type": "debugger.exception_replay.ExceptionReplayScissors",
      "key1": "val1",
      "key2": "val2",
      "version": "<scrubbed>"
    },
    "name": "flask.handle_user_exception",
    "parentID": "<scrubbed>",
    "resource": "flask.handle_user_exception",
    "service": "weblog",
    "spanID": "<scrubbed>",
    "start": "<scrubbed>",
    "traceID": "<scrubbed>"
  }
}