{
  "snapshot_0": {
    "duration": "<scrubbed>",
    "error": 1,
    "meta": {
      "_dd.debug.error.8.file": "/app/exception_replay_controller.py",
      "_dd.debug.error.8.function": "exceptionReplaySimple",
      "_dd.debug.error.8.line": "10",
      "_dd.debug.error.8.snapshot_id": "<scrubbed>",
      "_dd.debug.error.exception_id": "<scrubbed>",
      "component": "flask",
      "env": "system-tests",
      "error.debug_info_captured": "true",
      "error.message": "simple exception",
      "error.stack": "Traceback (most recent call last):\n  File \"/usr/local/lib/python3.11/site-packages/ddtrace/contrib/internal/flask/wrappers.py\", <scrubbed>",
      "error.type": "builtins.Exception",
      "key1": "val1",
      "key2": "val2",
      "version": "<scrubbed>"
    },
    "name": "flask.handle_user_exception",
    "parentID": "<scrubbed>",
    "resource": "flask.handle_user_exception",
    "service": "weblog",
    "spanID": "<scrubbed>",
    "start": "<scrubbed>",
    "traceID": "<scrubbed>"
  }
}