{
  "snapshot_0": {
    "duration": "<scrubbed>",
    "error": 1,
    "meta": {
      "_dd.debug.error.1.file": "/app/exception_replay_controller.py",
      "_dd.debug.error.1.function": "exception_replay_inner",
      "_dd.debug.error.1.line": "30",
      "_dd.debug.error.1.snapshot_id": "<scrubbed>",
      "_dd.debug.error.9.file": "/app/exception_replay_controller.py",
      "_dd.debug.error.9.function": "exception_replay_inner",
      "_dd.debug.error.9.line": "32",
      "_dd.debug.error.9.snapshot_id": "<scrubbed>",
      "_dd.debug.error.exception_id": "<scrubbed>",
      "component": "flask",
      "env": "system-tests",
      "error.debug_info_captured": "true",
      "error.message": "outer exception",
      "error.stack": "Traceback (most recent call last):\n  File \"/app/exception_replay_controller.py\", line 30, in exception_replay_inner\n    raise Ex<scrubbed>",
      "error.type": "builtins.Exception",
      "key1": "val1",
      "key2": "val2",
      "version": "<scrubbed>"
    },
    "name": "flask.handle_user_exception",
    "parentID": "<scrubbed>",
    "resource": "flask.handle_user_exception",
    "service": "weblog",
    "spanID": "<scrubbed>",
    "start": "<scrubbed>",
    "traceID": "<scrubbed>"
  }
}